Workbook

Sheet Dashboard

Sheet Cost Benefit Analysis 
B2: Project | I2: Project Manager
B3: Cost Benefit Analyst | I3: Nicholas Chavez
B5: Costs
B6: Direct Costs | I6: First Year | J6: Second Year | K6: Third Year | L6: Fourth Year | M6: Fifth Year | N6: Sixth Year | O6: Total
B7: Labor | I7: 1000 | J7: 1100 | K7: 1200 | L7: 1300 | M7: 1400 | N7: 1500 | O7: =SUM(I7:N7) -> 7500
B8: Materials | I8: 200 | J8: 220 | K8: 240 | L8: 260 | M8: 280 | N8: 300 | O8: =SUM(I8:N8) -> 1500
B9: Initial Project Investment | I9: 35000 | J9: $ | K9: $ | L9: $ | M9: $ | N9: $ | O9: =SUM(I9:N9) -> 35000
I10: $ | J10: $ | K10: $ | L10: $ | M10: $ | N10: $ | O10: =SUM(I10:N10) -> 0
I11: $ | J11: $ | K11: $ | L11: $ | M11: $ | N11: $ | O11: =SUM(I11:N11) -> 0
B12: Total | I12: =SUM(I7:I11) -> 36200 | J12: =SUM(J7:J11) -> 1320 | K12: =SUM(K7:K11) -> 1440 | L12: =SUM(L7:L11) -> 1560 | M12: =SUM(M7:M11) -> 1680 | N12: =SUM(N7:N11) -> 1800 | O12: =SUM(O7:O11) -> 44000
B14: Indirect Costs | I14: First Year | J14: Second Year | K14: Third Year | L14: Fourth Year | M14: Fifth Year | N14: Sixth Year | O14: Total
B15: Rent | I15: 1000 | J15: 1100 | K15: 1200 | L15: 1300 | M15: 1400 | N15: 1500 | O15: =SUM(I15:N15) -> 7500
B16: Utilities | I16: 200 | J16: 220 | K16: 240 | L16: 260 | M16: 280 | N16: 300 | O16: =SUM(I16:N16) -> 1500
I17: $ | J17: $ | K17: $ | L17: $ | M17: $ | N17: $ | O17: =SUM(I17:N17) -> 0
I18: $ | J18: $ | K18: $ | L18: $ | M18: $ | N18: $ | O18: =SUM(I18:N18) -> 0
I19: $ | J19: $ | K19: $ | L19: $ | M19: $ | N19: $ | O19: =SUM(I19:N19) -> 0
B20: Total | I20: =SUM(I15:I19) -> 1200 | J20: =SUM(J15:J19) -> 1320 | K20: =SUM(K15:K19) -> 1440 | L20: =SUM(L15:L19) -> 1560 | M20: =SUM(M15:M19) -> 1680 | N20: =SUM(N15:N19) -> 1800 | O20: =SUM(O15:O19) -> 9000
B22: One-time Costs | I22: First Year | J22: Second Year | K22: Third Year | L22: Fourth Year | M22: Fifth Year | N22: Sixth Year | O22: Total
B23: Equipment | I23: 500 | J23: 400 | K23: 600 | L23: 800 | M23: 500 | N23: 300 | O23: =SUM(I23:N23) -> 3100
B24: Annual Subscriptions | I24: 1000 | J24: 1000 | K24: 2000 | L24: 3000 | M24: 2000 | N24: 1500 | O24: =SUM(I24:N24) -> 10500
I25: $ | J25: $ | K25: $ | L25: $ | M25: $ | N25: $ | O25: =SUM(I25:N25) -> 0
I26: $ | J26: $ | K26: $ | L26: $ | M26: $ | N26: $ | O26: =SUM(I26:N26) -> 0
I27: $ | J27: $ | K27: $ | L27: $ | M27: $ | N27: $ | O27: =SUM(I27:N27) -> 0
B28: Total | I28: =SUM(I23:I27) -> 1500 | J28: =SUM(J23:J27) -> 1400 | K28: =SUM(K23:K27) -> 2600 | L28: =SUM(L23:L27) -> 3800 | M28: =SUM(M23:M27) -> 2500 | N28: =SUM(N23:N27) -> 1800 | O28: =SUM(O23:O27) -> 13600
B30: Opportunity Costs | I30: First Year | J30: Second Year | K30: Third Year | L30: Fourth Year | M30: Fifth Year | N30: Sixth Year | O30: Total
B31: Neglecting one project for another | I31: 1000 | J31: 1000 | K31: 1000 | L31: 1000 | M31: 1000 | N31: 1000 | O31: =SUM(I31:N31) -> 6000
I32: $ | J32: $ | K32: $ | L32: $ | M32: $ | N32: $ | O32: =SUM(I32:N32) -> 0
I33: $ | J33: $ | K33: $ | L33: $ | M33: $ | N33: $ | O33: =SUM(I33:N33) -> 0
I34: $ | J34: $ | K34: $ | L34: $ | M34: $ | N34: $ | O34: =SUM(I34:N34) -> 0
I35: $ | J35: $ | K35: $ | L35: $ | M35: $ | N35: $ | O35: =SUM(I35:N35) -> 0
B36: Total | I36: =SUM(I31:I35) -> 1000 | J36: =SUM(J31:J35) -> 1000 | K36: =SUM(K31:K35) -> 1000 | L36: =SUM(L31:L35) -> 1000 | M36: =SUM(M31:M35) -> 1000 | N36: =SUM(N31:N35) -> 1000 | O36: =SUM(O31:O35) -> 6000
B38: Contingency Costs | I38: First Year | J38: Second Year | K38: Third Year | L38: Fourth Year | M38: Fifth Year | N38: Sixth Year | O38: Total
B39: Neglecting one project for another | I39: 1000 | J39: 1000 | K39: 1000 | L39: 1000 | M39: 1000 | N39: 1000 | O39: =SUM(I39:N39) -> 6000
I40: $ | J40: $ | K40: $ | L40: $ | M40: $ | N40: $ | O40: =SUM(I40:N40) -> 0
I41: $ | J41: $ | K41: $ | L41: $ | M41: $ | N41: $ | O41: =SUM(I41:N41) -> 0
I42: $ | J42: $ | K42: $ | L42: $ | M42: $ | N42: $ | O42: =SUM(I42:N42) -> 0
I43: $ | J43: $ | K43: $ | L43: $ | M43: $ | N43: $ | O43: =SUM(I43:N43) -> 0
B44: Total | I44: =SUM(I39:I43) -> 1000 | J44: =SUM(J39:J43) -> 1000 | K44: =SUM(K39:K43) -> 1000 | L44: =SUM(L39:L43) -> 1000 | M44: =SUM(M39:M43) -> 1000 | N44: =SUM(N39:N43) -> 1000 | O44: =SUM(O39:O43) -> 6000
B46: Compliance Costs | I46: First Year | J46: Second Year | K46: Third Year | L46: Fourth Year | M46: Fifth Year | N46: Sixth Year | O46: Total
B47: Neglecting one project for another | I47: 1000 | J47: 1000 | K47: 1000 | L47: 1000 | M47: 1000 | N47: 1000 | O47: =SUM(I47:N47) -> 6000
...

Sheet Data
A1: Year | B1: Cost | C1: Revenue | D1: Profit
A2: 1 | B2: ='Cost Benefit Analysis '!I54 -> 41900 | C2: ='Cost Benefit Analysis '!I63 -> 15000 | D2: =C2-B2 -> -26900
A3: 2 | B3: ='Cost Benefit Analysis '!J54 -> 7040 | C3: ='Cost Benefit Analysis '!J63 -> 23040 | D3: =C3-B3 -> 16000
A4: 3 | B4: ='Cost Benefit Analysis '!K54 -> 8480 | C4: ='Cost Benefit Analysis '!K63 -> 22000 | D4: =C4-B4 -> 13520
A5: 4 | B5: ='Cost Benefit Analysis '!L54 -> 9920 | C5: ='Cost Benefit Analysis '!L63 -> 23000 | D5: =C5-B5 -> 13080
A6: 5 | B6: ='Cost Benefit Analysis '!M54 -> 8860 | C6: ='Cost Benefit Analysis '!M63 -> 29000 | D6: =C6-B6 -> 20140
A7: 6 | B7: ='Cost Benefit Analysis '!N54 -> 8400 | C7: ='Cost Benefit Analysis '!N63 -> 30000 | D7: =C7-B7 -> 21600
A10: Part | B10: Total
A11: Cost | B11: =SUM(B2:B7) -> 84600
A12: Profits | B12: =SUM(D2:D7) -> 57440
